<?xml version="1.0"?>
<robot name="robot">

  <link name="world">
    <origin xyz="0 0 0" rpy="0.0 0.0 0.0" />
  </link>


  <link name="base">
    <inertial>
      <mass value="100" />
      <material>Gazebo/Orange</material>
      <inertia ixx="0.2" ixy="0" ixz="0" iyy="0.2" iyz="0" izz="0.2" />
    </inertial>

    <visual>
      <geometry>
        <box size="1 1 0.1" />
      </geometry>

      <material name="steel">
        <color rgba="0 1 1 1.0" />
      </material>
    </visual>
  </link>


  <joint name="fixed" type="fixed">
    <parent link="world" />
    <child link="base" />
  </joint>



  <link name="slider">
    <inertial>
      <material>Gazebo/Orange</material>

      <mass value="1" />
      <inertia ixx="0.0016667" ixy="0" ixz="0" iyy="0.0016667" iyz="0" izz="0.0016667" />
    </inertial>
    <visual>
      <geometry>
        <box size="0.1 0.1 0.1" />
      </geometry>
      <material name="steel">
        <color rgba="1 0 0 1.0" />
      </material>
    </visual>
  </link>


  <joint name="joint1" type="prismatic">
    <origin xyz="0.0 0.0 0.1" rpy="0.0 0.0 0.0" />
    <parent link="base" />
    <child link="slider" />
    <axis xyz="1 0.0 0.0" />
    <limit lower="-0.5" upper="0.5" effort="1" velocity="0.1" />
  </joint>

  

  <link name="camera_link">
    <collision>
      <origin xyz="0 0 0" rpy="0 0 0" />
      <geometry>
        <box size="0.02 0.02 0.02" />
      </geometry>
    </collision>

    <visual>
      <origin xyz="0 0 0" rpy="0 0 0" />
      <geometry>
        <box size="0.02 0.02 0.02" />
      </geometry>
      <material name="red" />
    </visual>

    <inertial>
      <mass value="1e-5" />
      <origin xyz="0 0 0" rpy="0 0 0" />
      <inertia ixx="1e-6" ixy="0" ixz="0" iyy="1e-6" iyz="0" izz="1e-6" />
    </inertial>
  </link>

  <joint name="camera_joint" type="fixed">
    <axis xyz="0 0 0" />
    <origin xyz="0 0 0" rpy="0 0 1.57" />
    <parent link="slider" />
    <child link="camera_link" />
  </joint>


  <gazebo reference="camera_link">
    <sensor type="camera" name="camera1">
      <pose>-0.3 0 0 0 0 0</pose>
      <update_rate>30.0</update_rate>
      <camera name="head">
        <horizontal_fov>1.3962634</horizontal_fov>
        <image>
          <width>800</width>
          <height>800</height>
          <format>R8G8B8</format>
        </image>
        <clip>
          <near>0.02</near>
          <far>300</far>
        </clip>
        <noise>
          <type>gaussian</type>
          <!-- Noise is sampled independently per pixel on each frame.
               That pixel's noise value is added to each of its color
               channels, which at that point lie in the range [0,1]. -->
          <mean>0.0</mean>
          <stddev>0.007</stddev>
        </noise>
      </camera>
      <plugin name="camera_controller" filename="libgazebo_ros_camera.so">
        <alwaysOn>true</alwaysOn>
        <updateRate>1</updateRate>
        <cameraName>robot/camera1</cameraName>
        <imageTopicName>image_raw</imageTopicName>
        <cameraInfoTopicName>camera_info</cameraInfoTopicName>
        <frameName>camera_link</frameName>
        <hackBaseline>0.07</hackBaseline>
        <distortionK1>0.0</distortionK1>
        <distortionK2>0.0</distortionK2>
        <distortionK3>0.0</distortionK3>
        <distortionT1>0.0</distortionT1>
        <distortionT2>0.0</distortionT2>
      </plugin>
    </sensor>
  </gazebo>


  <transmission name="tran1">
    <type>transmission_interface/SimpleTransmission</type>
    <joint name="joint1">
      <hardwareInterface>hardware_interface/EffortJointInterface</hardwareInterface>
    </joint>
    <actuator name="motor1">
      <hardwareInterface>hardware_interface/EffortJointInterface</hardwareInterface>
      <mechanicalReduction>1</mechanicalReduction>
    </actuator>
  </transmission>


  <gazebo>
    <plugin name="gazebo_ros_control" filename="libgazebo_ros_control.so">
      <robotNamespace>/robot</robotNamespace>
    </plugin>
  </gazebo>


</robot>