<?xml version="1.0"?>
<robot name="robot">

  <link name="world">
    <origin xyz="0 0 0" rpy="0.0 0.0 0.0" />
  </link>


  <link name="base">
    <inertial>
      <mass value="100" />
      <material>Gazebo/Orange</material>
      <inertia ixx="0.2" ixy="0" ixz="0" iyy="0.2" iyz="0" izz="0.2" />
    </inertial>

    <visual>
      <geometry>
        <box size="1 1 0.1" />
      </geometry>

      <material name="steel">
        <color rgba="0 1 1 1.0" />
      </material>
    </visual>
  </link>


  <joint name="fixed" type="fixed">
    <parent link="world" />
    <child link="base" />
  </joint>



  <link name="slider">

    <collision>
      <origin xyz="0 0 0.15" rpy="0 0 0" />
      <geometry>
        <box size="0.1 0.2 0.1" />
      </geometry>
    </collision>




    <inertial>
      <material>Gazebo/Orange</material>
      <mass value="1" />
      <inertia ixx="0.0016667" ixy="0" ixz="0" iyy="0.0016667" iyz="0" izz="0.0016667" />
    </inertial>
    <visual>
      <origin xyz="0 0 0.15" rpy="0 0 0" />
      <geometry>
        <box size="0.1 0.2 0.1" />
      </geometry>
      <material name="steel">
        <color rgba="1 0 0 1.0" />
      </material>
    </visual>
  </link>


  <joint name="joint1" type="prismatic">
    <origin xyz="0.0 0.0 0.1" rpy="0.0 0.0 0.0" />
    <parent link="base" />
    <child link="slider" />
    <axis xyz="1 0.0 0.0" />
    <limit lower="-0.5" upper="0.5" effort="1" velocity="0.3" />
  </joint>

  

  <link name="camera_link">
   
    <collision>
      <origin xyz="0 0 0" rpy="0 0 0" />
      <geometry>
        <box size="0.02 0.02 0.02" />
      </geometry>
    </collision>

    <visual>
      <origin xyz="0 0 0.15" rpy="0 0 0" />
      <geometry>
        <box size="0.005 0.01 0.01" />
      </geometry>
      <material name="red" />
    </visual>

    <inertial>
      <mass value="1e-5" />
      <origin xyz="0 0 0" rpy="0 0 0" />
      <inertia ixx="1e-6" ixy="0" ixz="0" iyy="1e-6" iyz="0" izz="1e-6" />
    </inertial>
  </link>

  <joint name="camera_joint" type="fixed">
    
    <origin xyz="0 0 0.15" rpy="0 0 0" />
    <parent link="slider" />
    <child link="camera_link" />

    
    
  </joint>

  <joint name="cameraLeft_depth_joint" type="fixed">
    <origin xyz="0 0 0" rpy="-1.571 0 -1.571"/>
    <parent link="camera_link"/>
    <child link="cameraLeft_depth_link"/>
  </joint>


  <link name="cameraLeft_depth_link">
    <inertial>
      <mass value="1e-5" />
      <origin xyz="0 0 0" rpy="-1.571 0 -1.571" />
      <inertia ixx="1e-6" ixy="0" ixz="0" iyy="1e-6" iyz="0" izz="1e-6" />
    </inertial>
  </link>


  <gazebo reference="camera_link">
    <sensor type="depth" name="realsense_R200">
     
      <always_on>true</always_on>
      
      <camera>
          <horizontal_fov>1.3439</horizontal_fov>
          <image>
              <width>600</width>
              <height>480</height>
              <format>R8G8B8</format>
          </image>
          <depth_camera></depth_camera>
          <clip>
              <near>0.03</near>
              <far>2</far>
          </clip>
      </camera>
      <plugin name="camera_controller" filename="/home/pera/gazebo/gazebo_ros_pkgs/gazebo_plugins/build/devel/lib/libgazebo_ros_openni_kinect.so">
        <baseline>0.2</baseline>
        <alwaysOn>true</alwaysOn>
        <updateRate>10.0</updateRate>
        <cameraName>camera</cameraName>
        <frameName>cameraLeft_depth_link</frameName>
        <imageTopicName>rgb/image_raw</imageTopicName>
        <depthImageTopicName>depth/image_raw</depthImageTopicName>
        <pointCloudTopicName>depth/points</pointCloudTopicName>
        <cameraInfoTopicName>rgb/camera_info</cameraInfoTopicName>
        <depthImageCameraInfoTopicName>depth/camera_info</depthImageCameraInfoTopicName>
        <pointCloudCutoff>0.0</pointCloudCutoff>
            <hackBaseline>0.0</hackBaseline>
            <distortionK1>0.0</distortionK1>
            <distortionK2>0.0</distortionK2>
            <distortionK3>0.0</distortionK3>
            <distortionT1>0.0</distortionT1>
            <distortionT2>0.0</distortionT2>
        <CxPrime>0.0</CxPrime>
        <Cx>0.0</Cx>
        <Cy>0.0</Cy>
        <focalLength>0</focalLength>
        <hackBaseline>0</hackBaseline>
      </plugin>
    </sensor>
  </gazebo>


  <transmission name="tran1">
    <type>transmission_interface/SimpleTransmission</type>
    <joint name="joint1">
      <hardwareInterface>hardware_interface/EffortJointInterface</hardwareInterface>
    </joint>
    <actuator name="motor1">
      <hardwareInterface>hardware_interface/EffortJointInterface</hardwareInterface>
      <mechanicalReduction>1</mechanicalReduction>
    </actuator>
  </transmission>


  <gazebo>
    <plugin name="gazebo_ros_control" filename="libgazebo_ros_control.so">
      <robotNamespace>/robot</robotNamespace>
    </plugin>
  </gazebo>


</robot>